Traceback (most recent call last):
  File "/opt/miniconda3/envs/ssm-docs/lib/python3.9/site-packages/jupyter_cache/executors/utils.py", line 58, in single_nb_execution
    executenb(
  File "/opt/miniconda3/envs/ssm-docs/lib/python3.9/site-packages/nbclient/client.py", line 1204, in execute
    return NotebookClient(nb=nb, resources=resources, km=km, **kwargs).execute()
  File "/opt/miniconda3/envs/ssm-docs/lib/python3.9/site-packages/nbclient/util.py", line 84, in wrapped
    return just_run(coro(*args, **kwargs))
  File "/opt/miniconda3/envs/ssm-docs/lib/python3.9/site-packages/nbclient/util.py", line 62, in just_run
    return loop.run_until_complete(coro)
  File "/opt/miniconda3/envs/ssm-docs/lib/python3.9/asyncio/base_events.py", line 647, in run_until_complete
    return future.result()
  File "/opt/miniconda3/envs/ssm-docs/lib/python3.9/site-packages/nbclient/client.py", line 663, in async_execute
    await self.async_execute_cell(
  File "/opt/miniconda3/envs/ssm-docs/lib/python3.9/site-packages/nbclient/client.py", line 965, in async_execute_cell
    await self._check_raise_for_error(cell, cell_index, exec_reply)
  File "/opt/miniconda3/envs/ssm-docs/lib/python3.9/site-packages/nbclient/client.py", line 862, in _check_raise_for_error
    raise CellExecutionError.from_cell_and_msg(cell, exec_reply_content)
nbclient.exceptions.CellExecutionError: An error occurred while executing the following cell:
------------------
DATA_PATH = "/Users/Bantin/Documents/Stanford/Linderman-Shenoy/Kemere2008/extracted_data/H1217/H1217_hmm_data.npz"
vars_dict = np.load(DATA_PATH, allow_pickle=True)
------------------

[0;31m---------------------------------------------------------------------------[0m
[0;31mFileNotFoundError[0m                         Traceback (most recent call last)
Cell [0;32mIn [2], line 2[0m
[1;32m      1[0m DATA_PATH [38;5;241m=[39m [38;5;124m"[39m[38;5;124m/Users/Bantin/Documents/Stanford/Linderman-Shenoy/Kemere2008/extracted_data/H1217/H1217_hmm_data.npz[39m[38;5;124m"[39m
[0;32m----> 2[0m vars_dict [38;5;241m=[39m np[38;5;241m.[39mload(DATA_PATH, allow_pickle[38;5;241m=[39m[38;5;28;01mTrue[39;00m)

File [0;32m/opt/miniconda3/envs/ssm-docs/lib/python3.9/site-packages/autograd/tracer.py:48[0m, in [0;36mprimitive.<locals>.f_wrapped[0;34m(*args, **kwargs)[0m
[1;32m     46[0m     [38;5;28;01mreturn[39;00m new_box(ans, trace, node)
[1;32m     47[0m [38;5;28;01melse[39;00m:
[0;32m---> 48[0m     [38;5;28;01mreturn[39;00m [43mf_raw[49m[43m([49m[38;5;241;43m*[39;49m[43margs[49m[43m,[49m[43m [49m[38;5;241;43m*[39;49m[38;5;241;43m*[39;49m[43mkwargs[49m[43m)[49m

File [0;32m/opt/miniconda3/envs/ssm-docs/lib/python3.9/site-packages/numpy/lib/npyio.py:390[0m, in [0;36mload[0;34m(file, mmap_mode, allow_pickle, fix_imports, encoding)[0m
[1;32m    388[0m     own_fid [38;5;241m=[39m [38;5;28;01mFalse[39;00m
[1;32m    389[0m [38;5;28;01melse[39;00m:
[0;32m--> 390[0m     fid [38;5;241m=[39m stack[38;5;241m.[39menter_context([38;5;28;43mopen[39;49m[43m([49m[43mos_fspath[49m[43m([49m[43mfile[49m[43m)[49m[43m,[49m[43m [49m[38;5;124;43m"[39;49m[38;5;124;43mrb[39;49m[38;5;124;43m"[39;49m[43m)[49m)
[1;32m    391[0m     own_fid [38;5;241m=[39m [38;5;28;01mTrue[39;00m
[1;32m    393[0m [38;5;66;03m# Code to distinguish from NumPy binary files and pickles.[39;00m

[0;31mFileNotFoundError[0m: [Errno 2] No such file or directory: '/Users/Bantin/Documents/Stanford/Linderman-Shenoy/Kemere2008/extracted_data/H1217/H1217_hmm_data.npz'
FileNotFoundError: [Errno 2] No such file or directory: '/Users/Bantin/Documents/Stanford/Linderman-Shenoy/Kemere2008/extracted_data/H1217/H1217_hmm_data.npz'

